<?xml version="1.0" ?>
<sdf version="1.6">
<model name="quad_manipulator">
<pose frame=''>0 0 0.3 0 -0 0</pose>
<link name='base_link'>
      <pose frame=''>0 0 0 0 -0 0</pose>
      <inertial>
        <pose frame=''>-1e-06 -0.003068 -0.003158 0 -0 0</pose>
        <mass>1.5</mass>
        <inertia>
          <ixx>0.0347563</ixx>
          <ixy>0</ixy>
          <ixz>0</ixz>
          <iyy>0.0458929</iyy>
          <iyz>0</iyz>
          <izz>0.0977</izz>
        </inertia>
      </inertial>
      <collision name='base_link_collision'>
        <pose frame=''>0 0 0 0 -0 0</pose>
        <geometry>
          <mesh>
            <scale>1 1 1</scale>
            <uri>model://quad_manipulator/meshes/base_link.STL</uri>
          </mesh>
        </geometry>
      </collision>
      <collision name='base_link_fixed_joint_lump__arm_base_link_collision_1'>
        <pose frame=''>0 -0.07 -0.063 3.14159 -0 3.14159</pose>
        <geometry>
          <mesh>
            <scale>1 1 1</scale>
            <uri>model://quad_manipulator/meshes/arm_base_link.STL</uri>
          </mesh>
        </geometry>
      </collision>
      <collision name='base_link_fixed_joint_lump__camera_link_collision_2'>
        <pose frame=''>0 0.126 -0.057 3.14159 1.57079 3.14159</pose>
        <geometry>
          <mesh>
            <scale>1 1 1</scale>
            <uri>model://quad_manipulator/meshes/camera_link.STL</uri>
          </mesh>
        </geometry>
      </collision>
      <visual name='base_link_visual'>
        <pose frame=''>0 0 0 0 -0 0</pose>
        <geometry>
          <mesh>
            <scale>1 1 1</scale>
            <uri>model://quad_manipulator/meshes/base_link.STL</uri>
          </mesh>
        </geometry>
      </visual>
      <visual name='base_link_fixed_joint_lump__arm_base_link_visual_1'>
        <pose frame=''>0 -0.07 -0.063 3.14159 -0 3.14159</pose>
        <geometry>
          <mesh>
            <scale>1 1 1</scale>
            <uri>model://quad_manipulator/meshes/arm_base_link.STL</uri>
          </mesh>
        </geometry>
      </visual>
      <visual name='base_link_fixed_joint_lump__camera_link_visual_2'>
        <pose frame=''>0 0.126 -0.057 3.14159 1.57079 3.14159</pose>
        <geometry>
          <mesh>
            <scale>1 1 1</scale>
            <uri>model://quad_manipulator/meshes/camera_link.STL</uri>
          </mesh>
        </geometry>
      </visual>
    </link>
  <link name="/imu_link">
    <pose frame="">0 0 0 0 -0 0</pose>
    <inertial>
      <pose frame="">0 0 0 0 -0 0</pose>
      <mass>0.015</mass>
      <inertia>
        <ixx>1e-05</ixx>
        <ixy>0</ixy>
        <ixz>0</ixz>
        <iyy>1e-05</iyy>
        <iyz>0</iyz>
        <izz>1e-05</izz>
      </inertia>
    </inertial>
  </link>
  <joint name="/imu_joint" type="revolute">
    <child>/imu_link</child>
    <parent>base_link</parent>
    <axis>
      <xyz>1 0 0</xyz>
      <limit>
        <lower>0</lower>
        <upper>0</upper>
        <effort>0</effort>
        <velocity>0</velocity>
      </limit>
      <dynamics>
        <spring_reference>0</spring_reference>
        <spring_stiffness>0</spring_stiffness>
      </dynamics>
      <use_parent_model_frame>1</use_parent_model_frame>
    </axis>
  </joint>
  <link name="rotor_link_0">
    <pose frame="">0.19339 -0.19339 0.067478 0 0 0</pose>
    <!-- <pose frame="">0.13 -0.22 0.023 0 -0 0</pose> -->
    <inertial>
      <pose frame="">0 0 0 0 -0 0</pose>
      <mass>0.005</mass>
      <inertia>
        <ixx>9.75e-07</ixx>
        <ixy>0</ixy>
        <ixz>0</ixz>
        <iyy>0.000273104</iyy>
        <iyz>0</iyz>
        <izz>0.000274004</izz>
      </inertia>
    </inertial>
    <collision name="rotor_link_0_collision">
      <pose frame="">0 0 0 0 -0 0</pose>
      <geometry>
        <mesh>
          <scale>1 1 1</scale>
          <uri>model://quad_manipulator/meshes/dji_13455_prop_ccw.dae</uri>
        </mesh>
      </geometry>
      <surface>
        <contact>
          <ode/>
        </contact>
        <friction>
          <ode/>
        </friction>
      </surface>
    </collision>
    <visual name="rotor_link_0_visual">
      <pose frame="">0 0 0 0 -0 0</pose>
      <geometry>
        <mesh>
          <scale>1 1 1</scale>
          <uri>model://quad_manipulator/meshes/dji_13455_prop_ccw.dae</uri>
        </mesh>
      </geometry>
      <material>
        <script>
          <name>Gazebo/Blue</name>
          <uri>file://media/materials/scripts/gazebo.material</uri>
        </script>
      </material>
    </visual>
    <gravity>1</gravity>
    <velocity_decay/>
    <self_collide>0</self_collide>
  </link>
  <joint name="rotor_joint_0" type="revolute">
    <child>rotor_link_0</child>
    <parent>base_link</parent>
    <axis>
      <xyz>0 0 1</xyz>
      <limit>
        <lower>-1e+16</lower>
        <upper>1e+16</upper>
      </limit>
      <dynamics>
        <spring_reference>0</spring_reference>
        <spring_stiffness>0</spring_stiffness>
      </dynamics>
      <use_parent_model_frame>1</use_parent_model_frame>
    </axis>
  </joint>
  <link name="rotor_link_1">
    <pose frame="">-0.19339 0.19339 0.067478 0 -0 0</pose>
    <!-- <pose frame="">-0.13 0.2 0.023 0 -0 0</pose> -->
    <inertial>
      <pose frame="">0 0 0 0 -0 0</pose>
      <mass>0.005</mass>
      <inertia>
        <ixx>9.75e-07</ixx>
        <ixy>0</ixy>
        <ixz>0</ixz>
        <iyy>0.000273104</iyy>
        <iyz>0</iyz>
        <izz>0.000274004</izz>
      </inertia>
    </inertial>
    <collision name="rotor_link_1_collision">
      <pose frame="">0 0 0 0 -0 0</pose>
      <geometry>
        <mesh>
          <scale>1 1 1</scale>
          <uri>model://quad_manipulator/meshes/dji_13455_prop_ccw.dae</uri>
        </mesh>
      </geometry>
      <surface>
        <contact>
          <ode/>
        </contact>
        <friction>
          <ode/>
        </friction>
      </surface>
    </collision>
    <visual name="rotor_link_1_visual">
      <pose frame="">0 0 0 0 -0 0</pose>
      <geometry>
        <mesh>
          <scale>1 1 1</scale>
          <uri>model://quad_manipulator/meshes/dji_13455_prop_ccw.dae</uri>
        </mesh>
      </geometry>
      <material>
        <script>
          <name>Gazebo/DarkGrey</name>
          <uri>file://media/materials/scripts/gazebo.material</uri>
        </script>
      </material>
    </visual>
    <gravity>1</gravity>
    <velocity_decay/>
    <self_collide>0</self_collide>
  </link>
  <joint name="rotor_joint_1" type="revolute">
    <child>rotor_link_1</child>
    <parent>base_link</parent>
    <axis>
      <xyz>0 0 1</xyz>
      <limit>
        <lower>-1e+16</lower>
        <upper>1e+16</upper>
      </limit>
      <dynamics>
        <spring_reference>0</spring_reference>
        <spring_stiffness>0</spring_stiffness>
      </dynamics>
      <use_parent_model_frame>1</use_parent_model_frame>
    </axis>
  </joint>
  <link name="rotor_link_2">
    <pose frame="">0.19339 0.19339 0.067178 0 0 0</pose>
    <!-- <pose frame="">0.13 0.22 0.023 0 -0 0</pose> -->
    <inertial>
      <pose frame="">0 0 0 0 -0 0</pose>
      <mass>0.005</mass>
      <inertia>
        <ixx>9.75e-07</ixx>
        <ixy>0</ixy>
        <ixz>0</ixz>
        <iyy>0.000273104</iyy>
        <iyz>0</iyz>
        <izz>0.000274004</izz>
      </inertia>
    </inertial>
    <collision name="rotor_link_2_collision">
      <pose frame="">0 0 0 0 -0 0</pose>
      <geometry>
        <mesh>
          <scale>1 1 1</scale>
          <uri>model://quad_manipulator/meshes/dji_13455_prop_cw.dae</uri>
        </mesh>
      </geometry>
      <surface>
        <contact>
          <ode/>
        </contact>
        <friction>
          <ode/>
        </friction>
      </surface>
    </collision>
    <visual name="rotor_link_2_visual">
      <pose frame="">0 0 0 0 -0 0</pose>
      <geometry>
        <mesh>
          <scale>1 1 1</scale>
          <uri>model://quad_manipulator/meshes/dji_13455_prop_cw.dae</uri>
        </mesh>
      </geometry>
      <material>
        <script>
          <name>Gazebo/Blue</name>
          <uri>file://media/materials/scripts/gazebo.material</uri>
        </script>
      </material>
    </visual>
    <gravity>1</gravity>
    <velocity_decay/>
    <self_collide>0</self_collide>
  </link>
  <joint name="rotor_joint_2" type="revolute">
    <child>rotor_link_2</child>
    <parent>base_link</parent>
    <axis>
      <xyz>0 0 1</xyz>
      <limit>
        <lower>-1e+16</lower>
        <upper>1e+16</upper>
      </limit>
      <dynamics>
        <spring_reference>0</spring_reference>
        <spring_stiffness>0</spring_stiffness>
      </dynamics>
      <use_parent_model_frame>1</use_parent_model_frame>
    </axis>
  </joint>
  <link name="rotor_link_3">
    <pose frame="">-0.19339 -0.19339 0.067178 0 -0 0</pose>
    <!-- <pose frame="">-0.13 -0.2 0.023 0 -0 0</pose> -->
    <inertial>
      <pose frame="">0 0 0 0 -0 0</pose>
      <mass>0.005</mass>
      <inertia>
        <ixx>9.75e-07</ixx>
        <ixy>0</ixy>
        <ixz>0</ixz>
        <iyy>0.000273104</iyy>
        <iyz>0</iyz>
        <izz>0.000274004</izz>
      </inertia>
    </inertial>
    <collision name="rotor_link_3_collision">
      <pose frame="">0 0 0 0 -0 0</pose>
      <geometry>
        <mesh>
          <scale>1 1 1</scale>
          <uri>model://quad_manipulator/meshes/dji_13455_prop_cw.dae</uri>
        </mesh>
      </geometry>
      <surface>
        <contact>
          <ode/>
        </contact>
        <friction>
          <ode/>
        </friction>
      </surface>
    </collision>
    <visual name="rotor_link_3_visual">
      <pose frame="">0 0 0 0 -0 0</pose>
      <geometry>
        <mesh>
          <scale>1 1 1</scale>
          <uri>model://quad_manipulator/meshes/dji_13455_prop_cw.dae</uri>
        </mesh>
      </geometry>
      <material>
        <script>
          <name>Gazebo/DarkGrey</name>
          <uri>file://media/materials/scripts/gazebo.material</uri>
        </script>
      </material>
    </visual>
    <gravity>1</gravity>
    <velocity_decay/>
    <self_collide>0</self_collide>
  </link>
  <joint name="rotor_joint_3" type="revolute">
    <child>rotor_link_3</child>
    <parent>base_link</parent>
    <axis>
      <xyz>0 0 1</xyz>
      <limit>
        <lower>-1e+16</lower>
        <upper>1e+16</upper>
      </limit>
      <dynamics>
        <spring_reference>0</spring_reference>
        <spring_stiffness>0</spring_stiffness>
      </dynamics>
      <use_parent_model_frame>1</use_parent_model_frame>
    </axis>
  </joint>
  <plugin name="rosbag" filename="libgazebo_multirotor_base_plugin.so">
    <robotNamespace/>
    <linkName>base_link</linkName>
    <rotorVelocitySlowdownSim>10</rotorVelocitySlowdownSim>
  </plugin>
  <plugin name="front_right_motor_model" filename="libgazebo_motor_model.so">
    <robotNamespace/>
    <jointName>rotor_joint_0</jointName>
    <linkName>rotor_link_0</linkName>
    <turningDirection>ccw</turningDirection>
    <timeConstantUp>0.0125</timeConstantUp>
    <timeConstantDown>0.025</timeConstantDown>
    <maxRotVelocity>1100</maxRotVelocity>
    <motorConstant>8.54858e-06</motorConstant>
    <momentConstant>0.06</momentConstant>
    <commandSubTopic>/gazebo/command/motor_speed</commandSubTopic>
    <motorNumber>0</motorNumber>
    <rotorDragCoefficient>0.000806428</rotorDragCoefficient>
    <rollingMomentCoefficient>1e-06</rollingMomentCoefficient>
    <motorSpeedPubTopic>/motor_speed/0</motorSpeedPubTopic>
    <rotorVelocitySlowdownSim>10</rotorVelocitySlowdownSim>
  </plugin>
  <plugin name="back_left_motor_model" filename="libgazebo_motor_model.so">
    <robotNamespace/>
    <jointName>rotor_joint_1</jointName>
    <linkName>rotor_link_1</linkName>
    <turningDirection>ccw</turningDirection>
    <timeConstantUp>0.0125</timeConstantUp>
    <timeConstantDown>0.025</timeConstantDown>
    <maxRotVelocity>1100</maxRotVelocity>
    <motorConstant>8.54858e-06</motorConstant>
    <momentConstant>0.06</momentConstant>
    <commandSubTopic>/gazebo/command/motor_speed</commandSubTopic>
    <motorNumber>1</motorNumber>
    <rotorDragCoefficient>0.000806428</rotorDragCoefficient>
    <rollingMomentCoefficient>1e-06</rollingMomentCoefficient>
    <motorSpeedPubTopic>/motor_speed/1</motorSpeedPubTopic>
    <rotorVelocitySlowdownSim>10</rotorVelocitySlowdownSim>
  </plugin>
  <plugin name="front_left_motor_model" filename="libgazebo_motor_model.so">
    <robotNamespace/>
    <jointName>rotor_joint_2</jointName>
    <linkName>rotor_link_2</linkName>
    <turningDirection>cw</turningDirection>
    <timeConstantUp>0.0125</timeConstantUp>
    <timeConstantDown>0.025</timeConstantDown>
    <maxRotVelocity>1100</maxRotVelocity>
    <motorConstant>8.54858e-06</motorConstant>
    <momentConstant>0.06</momentConstant>
    <commandSubTopic>/gazebo/command/motor_speed</commandSubTopic>
    <motorNumber>2</motorNumber>
    <rotorDragCoefficient>0.000806428</rotorDragCoefficient>
    <rollingMomentCoefficient>1e-06</rollingMomentCoefficient>
    <motorSpeedPubTopic>/motor_speed/2</motorSpeedPubTopic>
    <rotorVelocitySlowdownSim>10</rotorVelocitySlowdownSim>
  </plugin>
  <plugin name="back_right_motor_model" filename="libgazebo_motor_model.so">
    <robotNamespace/>
    <jointName>rotor_joint_3</jointName>
    <linkName>rotor_link_3</linkName>
    <turningDirection>cw</turningDirection>
    <timeConstantUp>0.0125</timeConstantUp>
    <timeConstantDown>0.025</timeConstantDown>
    <maxRotVelocity>1100</maxRotVelocity>
    <motorConstant>8.54858e-06</motorConstant>
    <momentConstant>0.06</momentConstant>
    <commandSubTopic>/gazebo/command/motor_speed</commandSubTopic>
    <motorNumber>3</motorNumber>
    <rotorDragCoefficient>0.000806428</rotorDragCoefficient>
    <rollingMomentCoefficient>1e-06</rollingMomentCoefficient>
    <motorSpeedPubTopic>/motor_speed/3</motorSpeedPubTopic>
    <rotorVelocitySlowdownSim>10</rotorVelocitySlowdownSim>
  </plugin>
  <plugin name="gps_plugin" filename="libgazebo_gps_plugin.so">
    <robotNamespace/>
    <gpsNoise>false</gpsNoise>
  </plugin>
  <plugin name="mavlink_interface" filename="libgazebo_mavlink_interface.so">
    <robotNamespace/>
    <imuSubTopic>/imu</imuSubTopic>
    <gpsSubTopic>/gps</gpsSubTopic>
    <mavlink_addr>INADDR_ANY</mavlink_addr>
    <mavlink_udp_port>14560</mavlink_udp_port>
    <serialEnabled>false</serialEnabled>
    <serialDevice>/dev/ttyACM0</serialDevice>
    <baudRate>921600</baudRate>
    <qgc_addr>INADDR_ANY</qgc_addr>
    <qgc_udp_port>14550</qgc_udp_port>
    <hil_mode>false</hil_mode>
    <hil_state_level>false</hil_state_level>
    <vehicle_is_tailsitter>false</vehicle_is_tailsitter>
    <send_odometry>false</send_odometry>
    <motorSpeedCommandPubTopic>/gazebo/command/motor_speed</motorSpeedCommandPubTopic>
    <control_channels>
      <channel name="rotor1">
        <input_index>0</input_index>
        <input_offset>0</input_offset>
        <input_scaling>1000</input_scaling>
        <zero_position_disarmed>0</zero_position_disarmed>
        <zero_position_armed>100</zero_position_armed>
        <joint_control_type>velocity</joint_control_type>
      </channel>
      <channel name="rotor2">
        <input_index>1</input_index>
        <input_offset>0</input_offset>
        <input_scaling>1000</input_scaling>
        <zero_position_disarmed>0</zero_position_disarmed>
        <zero_position_armed>100</zero_position_armed>
        <joint_control_type>velocity</joint_control_type>
      </channel>
      <channel name="rotor3">
        <input_index>2</input_index>
        <input_offset>0</input_offset>
        <input_scaling>1000</input_scaling>
        <zero_position_disarmed>0</zero_position_disarmed>
        <zero_position_armed>100</zero_position_armed>
        <joint_control_type>velocity</joint_control_type>
      </channel>
      <channel name="rotor4">
        <input_index>3</input_index>
        <input_offset>0</input_offset>
        <input_scaling>1000</input_scaling>
        <zero_position_disarmed>0</zero_position_disarmed>
        <zero_position_armed>100</zero_position_armed>
        <joint_control_type>velocity</joint_control_type>
      </channel>
      <channel name="rotor5">
        <input_index>4</input_index>
        <input_offset>1</input_offset>
        <input_scaling>324.6</input_scaling>
        <zero_position_disarmed>0</zero_position_disarmed>
        <zero_position_armed>0</zero_position_armed>
        <joint_control_type>velocity</joint_control_type>
        <joint_control_pid>
          <p>0.1</p>
          <i>0</i>
          <d>0</d>
          <iMax>0.0</iMax>
          <iMin>0.0</iMin>
          <cmdMax>2</cmdMax>
          <cmdMin>-2</cmdMin>
        </joint_control_pid>
        <joint_name>zephyr_delta_wing::propeller_joint</joint_name>
      </channel>
      <channel name="rotor6">
        <input_index>5</input_index>
        <input_offset>0</input_offset>
        <input_scaling>0.524</input_scaling>
        <zero_position_disarmed>0</zero_position_disarmed>
        <zero_position_armed>0</zero_position_armed>
        <joint_control_type>position</joint_control_type>
        <joint_name>zephyr_delta_wing::flap_left_joint</joint_name>
        <joint_control_pid>
          <p>10.0</p>
          <i>0</i>
          <d>0</d>
          <iMax>0</iMax>
          <iMin>0</iMin>
          <cmdMax>20</cmdMax>
          <cmdMin>-20</cmdMin>
        </joint_control_pid>
      </channel>
      <channel name="rotor7">
        <input_index>6</input_index>
        <input_offset>0</input_offset>
        <input_scaling>0.524</input_scaling>
        <zero_position_disarmed>0</zero_position_disarmed>
        <zero_position_armed>0</zero_position_armed>
        <joint_control_type>position</joint_control_type>
        <joint_name>zephyr_delta_wing::flap_right_joint</joint_name>
        <joint_control_pid>
          <p>10.0</p>
          <i>0</i>
          <d>0</d>
          <iMax>0</iMax>
          <iMin>0</iMin>
          <cmdMax>20</cmdMax>
          <cmdMin>-20</cmdMin>
        </joint_control_pid>
      </channel>
      <channel name="rotor8">
        <input_index>7</input_index>
        <input_offset>0</input_offset>
        <input_scaling>0.524</input_scaling>
        <zero_position_disarmed>0</zero_position_disarmed>
        <zero_position_armed>0</zero_position_armed>
        <joint_control_type>position</joint_control_type>
      </channel>
    </control_channels>
  </plugin>
  <static>0</static>
  <plugin name="rotors_gazebo_imu_plugin" filename="libgazebo_imu_plugin.so">
    <robotNamespace/>
    <linkName>/imu_link</linkName>
    <imuTopic>/imu</imuTopic>
    <gyroscopeNoiseDensity>0.0003394</gyroscopeNoiseDensity>
    <gyroscopeRandomWalk>3.8785e-05</gyroscopeRandomWalk>
    <gyroscopeBiasCorrelationTime>1000.0</gyroscopeBiasCorrelationTime>
    <gyroscopeTurnOnBiasSigma>0.0087</gyroscopeTurnOnBiasSigma>
    <accelerometerNoiseDensity>0.004</accelerometerNoiseDensity>
    <accelerometerRandomWalk>0.006</accelerometerRandomWalk>
    <accelerometerBiasCorrelationTime>300.0</accelerometerBiasCorrelationTime>
    <accelerometerTurnOnBiasSigma>0.196</accelerometerTurnOnBiasSigma>
  </plugin>



<link name='arm_link_1'>
<pose frame=''>0 -0.07 -0.08375 1.5708 -0 -0</pose>
<inertial>
  <pose frame=''>-3e-06 0.023881 0 0 -0 0</pose>
  <mass>0.033119</mass>
  <inertia>
    <ixx>0.0033119</ixx>
    <ixy>0</ixy>
    <ixz>0</ixz>
    <iyy>0.0033119</iyy>
    <iyz>0</iyz>
    <izz>0.0033119</izz>
  </inertia>
</inertial>
<collision name='arm_link_1_collision'>
  <pose frame=''>0 0 0 0 -0 0</pose>
  <geometry>
    <mesh>
      <scale>1 1 1</scale>
      <uri>model://quad_manipulator/meshes/arm_link_1.STL</uri>
    </mesh>
  </geometry>
</collision>
<visual name='arm_link_1_visual'>
  <pose frame=''>0 0 0 0 -0 0</pose>
  <geometry>
    <mesh>
      <scale>1 1 1</scale>
      <uri>model://quad_manipulator/meshes/arm_link_1.STL</uri>
    </mesh>
  </geometry>
</visual>
</link>
<joint name='arm_joint_1' type='revolute'>
<child>arm_link_1</child>
<parent>base_link</parent>
<axis>
  <xyz>-0 -4e-06 1</xyz>
  <limit>
    <lower>-3.14</lower>
    <upper>3.14</upper>
    <effort>10</effort>
    <velocity>1</velocity>
  </limit>
  <dynamics>
    <spring_reference>0</spring_reference>
    <spring_stiffness>0</spring_stiffness>
  </dynamics>
  <use_parent_model_frame>1</use_parent_model_frame>
</axis>
</joint>
<link name='arm_link_2'>
<pose frame=''>0 -0.07 -0.11375 2.0944 -0 -0</pose>
<inertial>
  <pose frame=''>-0.007708 -0.039711 0.055524 0 -0 0</pose>
  <mass>0.097521</mass>
  <inertia>
    <ixx>0.0097521</ixx>
    <ixy>0</ixy>
    <ixz>0</ixz>
    <iyy>0.0097521</iyy>
    <iyz>0</iyz>
    <izz>0.0097521</izz>
  </inertia>
</inertial>
<collision name='arm_link_2_collision'>
  <pose frame=''>0 0 0 0 -0 0</pose>
  <geometry>
    <mesh>
      <scale>1 1 1</scale>
      <uri>model://quad_manipulator/meshes/arm_link_2.STL</uri>
    </mesh>
  </geometry>
</collision>
<visual name='arm_link_2_visual'>
  <pose frame=''>0 0 0 0 -0 0</pose>
  <geometry>
    <mesh>
      <scale>1 1 1</scale>
      <uri>model://quad_manipulator/meshes/arm_link_2.STL</uri>
    </mesh>
  </geometry>
</visual>
</link>
<joint name='arm_joint_2' type='revolute'>
<child>arm_link_2</child>
<parent>arm_link_1</parent>
<axis>
  <xyz>1 -0 0</xyz>
  <limit>
    <lower>-0.8</lower>
    <upper>3.0</upper>
    <effort>10</effort>
    <velocity>1</velocity>
  </limit>
  <dynamics>
    <spring_reference>0</spring_reference>
    <spring_stiffness>0</spring_stiffness>
  </dynamics>
  <use_parent_model_frame>1</use_parent_model_frame>
</axis>
</joint>
<link name='arm_link_3'>
  <pose frame=''>0 -0.191091 -0.183663 1.5708 -0 -0</pose>
  <inertial>
    <pose frame=''>0.041927 0.030318 -0.088736 0 -0 0</pose>
    <mass>0.027976</mass>
    <inertia>
      <ixx>0.0027976</ixx>
      <ixy>0</ixy>
      <ixz>0</ixz>
      <iyy>0.0027976</iyy>
      <iyz>0</iyz>
      <izz>0.0027976</izz>
    </inertia>
  </inertial>
  <collision name='arm_link_3_collision'>
    <pose frame=''>0 0 0 0 -0 0</pose>
    <geometry>
      <mesh>
        <scale>1 1 1</scale>
        <uri>model://quad_manipulator/meshes/arm_link_3.STL</uri>
      </mesh>
    </geometry>
  </collision>
  <visual name='arm_link_3_visual'>
    <pose frame=''>0 0 0 0 -0 0</pose>
    <geometry>
      <mesh>
        <scale>1 1 1</scale>
        <uri>model://quad_manipulator/meshes/arm_link_3.STL</uri>
      </mesh>
    </geometry>
  </visual>
</link>
<joint name='arm_joint_3' type='revolute'>
<child>arm_link_3</child>
<parent>arm_link_2</parent>
<axis>
  <xyz>1 -0 0</xyz>
  <limit>
    <lower>-5.4</lower>
    <upper>0</upper>
    <effort>10</effort>
    <velocity>1</velocity>
  </limit>
  <dynamics>
    <spring_reference>0</spring_reference>
    <spring_stiffness>0</spring_stiffness>
  </dynamics>
  <use_parent_model_frame>1</use_parent_model_frame>
</axis>
</joint>
<link name='grasp_link_1'>
<pose frame=''>-0.021589 -0.045577 -0.183662 3e-06 2e-06 -0.47487</pose>
<inertial>
  <pose frame=''>-0.012047 0.027271 -0.002383 0 -0 0</pose>
  <mass>0.016743</mass>
  <inertia>
  <ixx>0.0016743</ixx>
  <ixy>0</ixy>
  <ixz>0</ixz>
  <iyy>0.0016743</iyy>
  <iyz>0</iyz>
  <izz>0.0016743</izz>
  </inertia>
</inertial>
<collision name='grasp_link_1_collision'>
    <pose frame=''>0 0 0 0 -0 0</pose>
    <geometry>
      <mesh>
        <scale>1 1 1</scale>
        <uri>model://quad_manipulator/meshes/grasp_link_1.STL</uri>
      </mesh>
    </geometry>
</collision>
<visual name='grasp_link_1_visual'>
  <pose frame=''>0 0 0 0 -0 0</pose>
  <geometry>
    <mesh>
      <scale>1 1 1</scale>
      <uri>model://quad_manipulator/meshes/grasp_link_1.STL</uri>
    </mesh>
  </geometry>
</visual>
</link>
<joint name='grasp_joint_1' type='revolute'>
<child>grasp_link_1</child>
<parent>arm_link_3</parent>
<axis>
  <xyz>-0 -4e-06 1</xyz>Z
  <limit>
    <lower>0</lower>
    <upper>0.8</upper>
    <effort>0</effort>
    <velocity>0</velocity>
  </limit>
  <dynamics>
    <spring_reference>0</spring_reference>
    <spring_stiffness>0</spring_stiffness>
  </dynamics>
  <use_parent_model_frame>1</use_parent_model_frame>
</axis>
</joint>
<link name='grasp_link_2'>
<pose frame=''>0.021589 -0.045577 -0.183662 4e-06 -1e-06 0.246759</pose>
<inertial>
  <pose frame=''>0.005608 0.029333 -0.002378 0 -0 0</pose>
  <mass>0.016711</mass>
  <inertia>
    <ixx>0.0016711</ixx>
    <ixy>0</ixy>
    <ixz>0</ixz>
    <iyy>0.0016711</iyy>
    <iyz>0</iyz>
    <izz>0.0016711</izz>
  </inertia>
</inertial>
<collision name='grasp_link_2_collision'>
  <pose frame=''>0 0 0 0 -0 0</pose>
  <geometry>
    <mesh>
      <scale>1 1 1</scale>
      <uri>model://quad_manipulator/meshes/grasp_link_2.STL</uri>
    </mesh>
  </geometry>
</collision>
<visual name='grasp_link_2_visual'>
  <pose frame=''>0 0 0 0 -0 0</pose>
  <geometry>
    <mesh>
      <scale>1 1 1</scale>
      <uri>model://quad_manipulator/meshes/grasp_link_2.STL</uri>
    </mesh>
  </geometry>
</visual>
</link>
<joint name='grasp_joint_2' type='revolute'>
<child>grasp_link_2</child>
<parent>arm_link_3</parent>
<axis>
  <xyz>-0 -4e-06 1</xyz>
  <limit>
    <lower>-0.8</lower>
    <upper>0</upper>
    <effort>10</effort>
    <velocity>1</velocity>
  </limit>
  <dynamics>
    <spring_reference>0</spring_reference>
    <spring_stiffness>0</spring_stiffness>
  </dynamics>
  <use_parent_model_frame>1</use_parent_model_frame>
</axis>
</joint>

<!-- <link name='arm_link_1'>
      <pose frame=''>0 -0.07 -0.08375 1.5708 -0 -0</pose>
      <inertial>
        <pose frame=''>-3e-06 -0.008619 0 0 -0 0</pose>
        <mass>0.033119</mass>
        <inertia>
          <ixx>0.0033119</ixx>
          <ixy>0</ixy>
          <ixz>0</ixz>
          <iyy>0.0033119</iyy>
          <iyz>0</iyz>
          <izz>0.0033119</izz>
        </inertia>
      </inertial>
      <collision name='arm_link_1_collision'>
        <pose frame=''>0 0 0 0 -0 0</pose>
        <geometry>
          <mesh>
            <scale>1 1 1</scale>
            <uri>model://quad_manipulator/meshes/arm_link_1.STL</uri>
          </mesh>
        </geometry>
      </collision>
      <visual name='arm_link_1_visual'>
        <pose frame=''>0 0 0 0 -0 0</pose>
        <geometry>
          <mesh>
            <scale>1 1 1</scale>
            <uri>model://quad_manipulator/meshes/arm_link_1.STL</uri>
          </mesh>
        </geometry>
      </visual>
    </link>
    <joint name='arm_joint_1' type='revolute'>
      <child>arm_link_1</child>
      <parent>base_link</parent>
      <axis>
        <xyz>-0 -4e-06 1</xyz>
        <limit>
          <lower>-3.14</lower>
          <upper>3.14</upper>
          <effort>10</effort>
          <velocity>1</velocity>
        </limit>
        <dynamics>
          <spring_reference>0</spring_reference>
          <spring_stiffness>0</spring_stiffness>
        </dynamics>
        <use_parent_model_frame>1</use_parent_model_frame>
      </axis>
    </joint>
    <link name='arm_link_2'>
      <pose frame=''>0 -0.07 -0.11375 2.0944 -0 -0</pose>
      <inertial>
        <pose frame=''>-0.000267 1.4e-05 0.069913 0 -0 0</pose>
        <mass>0.097521</mass>
        <inertia>
          <ixx>0.0097521</ixx>
          <ixy>-2.3036e-11</ixy>
          <ixz>5.4064e-13</ixz>
          <iyy>0.0097521</iyy>
          <iyz>-3.8194e-12</iyz>
          <izz>0.0097521</izz>
        </inertia>
      </inertial>
      <collision name='arm_link_2_collision'>
        <pose frame=''>0 0 0 0 -0 0</pose>
        <geometry>
          <mesh>
            <scale>1 1 1</scale>
            <uri>model://quad_manipulator/meshes/arm_link_2.STL</uri>
          </mesh>
        </geometry>
      </collision>
      <visual name='arm_link_2_visual'>
        <pose frame=''>0 0 0 0 -0 0</pose>
        <geometry>
          <mesh>
            <scale>1 1 1</scale>
            <uri>model://quad_manipulator/meshes/arm_link_2.STL</uri>
          </mesh>
        </geometry>
      </visual>
    </link>
    <joint name='arm_joint_2' type='revolute'>
      <child>arm_link_2</child>
      <parent>arm_link_1</parent>
      <axis>
        <xyz>1 -0 0</xyz>
        <limit>
          <lower>-0.8</lower>
          <upper>3</upper>
          <effort>10</effort>
          <velocity>1</velocity>
        </limit>
        <dynamics>
          <spring_reference>0</spring_reference>
          <spring_stiffness>0</spring_stiffness>
        </dynamics>
        <use_parent_model_frame>1</use_parent_model_frame>
      </axis>
    </joint>
    <link name='arm_link_3'>
      <pose frame=''>0 -0.191091 -0.183663 1.5708 -0 -0</pose>
      <inertial>
        <pose frame=''>-2.7e-05 -0.00189 -0.084066 0 -0 0</pose>
        <mass>0.014245</mass>
        <inertia>
          <ixx>0.0014</ixx>
          <ixy>-1.1379e-09</ixy>
          <ixz>-1.6872e-08</ixz>
          <iyy>0.0014</iyy>
          <iyz>-1.1899e-06</iyz>
          <izz>0.0014</izz>
        </inertia>
      </inertial>
      <collision name='arm_link_3_collision'>
        <pose frame=''>0 0 0 0 -0 0</pose>
        <geometry>
          <mesh>
            <scale>1 1 1</scale>
            <uri>model://quad_manipulator/meshes/arm_link_3.STL</uri>
          </mesh>
        </geometry>
      </collision>
      <visual name='arm_link_3_visual'>
        <pose frame=''>0 0 0 0 -0 0</pose>
        <geometry>
          <mesh>
            <scale>1 1 1</scale>
            <uri>model://quad_manipulator/meshes/arm_link_3.STL</uri>
          </mesh>
        </geometry>
      </visual>
    </link>
    <joint name='arm_joint_3' type='revolute'>
      <child>arm_link_3</child>
      <parent>arm_link_2</parent>
      <axis>
        <xyz>1 -0 0</xyz>
        <limit>
          <lower>-5.4</lower>
          <upper>0</upper>
          <effort>10</effort>
          <velocity>1</velocity>
        </limit>
        <dynamics>
          <spring_reference>0</spring_reference>
          <spring_stiffness>0</spring_stiffness>
        </dynamics>
        <use_parent_model_frame>1</use_parent_model_frame>
      </axis>
    </joint>
    <link name='grasp_link_1'>
      <pose frame=''>-0.021589 -0.045577 -0.183662 3e-06 2e-06 -0.47487</pose>
      <inertial>
        <pose frame=''>-0.012047 0.027271 -0.002383 0 -0 0</pose>
        <mass>0.017045</mass>
        <inertia>
            <ixx>0.0016743</ixx>
            <ixy>-3.8936e-07</ixy>
            <ixz>1.236e-08</ixz>
            <iyy>0.0016743</iyy>
            <iyz>6.8467e-08</iyz>
            <izz>0.0016743</izz>
        </inertia>
      </inertial>
      <collision name='grasp_link_1_collision'>
        <pose frame=''>0 0 0 0 -0 0</pose>
        <geometry>
          <mesh>
            <scale>1 1 1</scale>
            <uri>model://quad_manipulator/meshes/grasp_link_1.STL</uri>
          </mesh>
        </geometry>
      </collision>
      <visual name='grasp_link_1_visual'>
        <pose frame=''>0 0 0 0 -0 0</pose>
        <geometry>
          <mesh>
            <scale>1 1 1</scale>
            <uri>model://quad_manipulator/meshes/grasp_link_1.STL</uri>
          </mesh>
        </geometry>
      </visual>
    </link>
    <joint name='grasp_joint_1' type='revolute'>
      <child>grasp_link_1</child>
      <parent>arm_link_3</parent>
      <axis>
        <xyz>-0 -4e-06 1</xyz>
        <limit>
          <lower>0</lower>
          <upper>0.8</upper>
          <effort>10</effort>
          <velocity>1</velocity>
        </limit>
        <dynamics>
          <spring_reference>0</spring_reference>
          <spring_stiffness>0</spring_stiffness>
        </dynamics>
        <use_parent_model_frame>1</use_parent_model_frame>
      </axis>
    </joint>
    <link name='grasp_link_2'>
      <pose frame=''>0.021589 -0.045577 -0.183662 4e-06 -1e-06 0.246759</pose>
      <inertial>
        <pose frame=''>0.005608 0.029333 -0.002378 0 -0 0</pose>
        <mass>0.017045</mass>
        <inertia>
            <ixx>0.0016743</ixx>
            <ixy>-3.8936e-07</ixy>
            <ixz>1.236e-08</ixz>
            <iyy>0.0016743</iyy>
            <iyz>6.8467e-08</iyz>
            <izz>0.0016743</izz>
        </inertia>
      </inertial>
      <collision name='grasp_link_2_collision'>
        <pose frame=''>0 0 0 0 -0 0</pose>
        <geometry>
          <mesh>
            <scale>1 1 1</scale>
            <uri>model://quad_manipulator/meshes/grasp_link_2.STL</uri>
          </mesh>
        </geometry>
      </collision>
      <visual name='grasp_link_2_visual'>
        <pose frame=''>0 0 0 0 -0 0</pose>
        <geometry>
          <mesh>
            <scale>1 1 1</scale>
            <uri>model://quad_manipulator/meshes/grasp_link_2.STL</uri>
          </mesh>
        </geometry>
      </visual>
    </link>
    <joint name='grasp_joint_2' type='revolute'>
      <child>grasp_link_2</child>
      <parent>arm_link_3</parent>
      <axis>
        <xyz>-0 -4e-06 1</xyz>
        <limit>
          <lower>-0.8</lower>
          <upper>0</upper>
          <effort>10</effort>
          <velocity>1</velocity>
        </limit>
        <dynamics>
          <spring_reference>0</spring_reference>
          <spring_stiffness>0</spring_stiffness>
        </dynamics>
        <use_parent_model_frame>1</use_parent_model_frame>
      </axis>
    </joint> -->


  </model>
</sdf>
